Workbook

Sheet Suivi
A1: Date | B1: Motif | C1: Catégorie | D1: Dépense | E1: Recette | F1: Payeur | G1: Remboursé | H1: Facture
A2: 45746 | B2: Film | C2: CCMP | D2: 3.99 | F2: Mikhail | G2: oui | H2: oui
A3: 45760 | B3: Piles | C3: salle ins | D3: 7.1 | F3: Alexis Derail | G3: oui
A4: 45817 | B4: dettes | C4: Gastro | D4: 13.34 | F4: Solène Losantos | G4: oui
A5: 45818 | B5: concerts | C5: classique | D5: 502 | F5: Adam Bidi | G5: oui | H5: oui
A6: 45824 | B6: buffet concert BDA | C6: Gastro | D6: 246.79 | F6: Solène Losantos | G6: oui | H6: oui
A7: 45826 | B7: Frais dossier passace | C7: banque | D7: 50 | H7: CEIDF
A8: 45829 | B8: soirée 1 | C8: créa | D8: 56.11 | F8: Josephine Peronne | G8: oui | H8: oui
A9: 45829 | B9: Misanthrope + Scapin | C9: théâtre | D9: 450 | H9: Comédie Française
A10: 45832 | B10: soirée 26/06 | C10: créa | D10: 50.28 | F10: Joséphine Peronne | G10: oui | H10: oui | O10: Pôle | Q10: Budget | R10: Réel | S10: Delta
A11: 45833 | B11: Cotisation salle ins' | C11: Général | E11: 5 | F11: Killian Bujon | O11: Théâtre | Q11: 600 | R11: =-'théâtre'!L7 -> 538 | S11: =R11-Q11 -> -62
A12: 45839 | B12: parrainage | C12: Général | D12: 600 | H12: Th. Renaissance | J12: Total dépenses | K12: =SUM(D2:D200) -> 9462.65 | O12: Musique | Q12: 700 | R12: =-classique!L7 -> 372 | S12: =R12-Q12 -> -328
A13: 45840 | B13: Constellation | C13: Général | E13: 500 | F13: PCV | H13: PCV | J13: Total recettes | K13: =SUM(E2:E200) -> 9755.35 | O13: Art créa | Q13: 600 | R13: =-'créa'!L7 -> 528.43 | S13: =R13-Q13 -> -71.57
A14: 45895 | B14: Vente matos | C14: salle ins | E14: 70 | F14: Alexis Derail | G14: oui | J14: Total net | K14: =K13-K12 -> 292.7 | O14: Sorties/ Expo | Q14: 200 | R14: 0 | S14: =R14-Q14 -> -200
A15: 45900 | B15: BALM | C15: Général | D15: 369 | F15: Tom Back | G15: oui | O15: Danse/ Comédie musicale | Q15: 300 | R15: =-'Comédie'!L7 -> 222 | S15: =R15-Q15 -> -78
A16: 45902 | B16: BALM | C16: Général | D16: 83.69 | F16: Alexandre Viot | G16: oui | O16: Cinéma | Q16: 200 | R16: =-'ciné'!L7 -> 126.93 | S16: =R16-Q16 -> -73.07
A17: 45902 | B17: BALM | C17: Général | D17: 41.34 | F17: Romain Lelaidier | G17: oui | O17: Bibliothèque | Q17: 50 | R17: 0 | S17: =R17-Q17 -> -50
A18: 45905 | B18: Soirée créa | C18: Créa | D18: 6.98 | F18: Romain Lelaidier | G18: oui
A19: 45906 | B19: Journée BDA | C19: Général | D19: 40 | F19: Romain Lelaidier | G19: oui | O19: Total | Q19: =SUM(Q11:Q18) -> 2650 | R19: =SUM(R11:R18) -> 1787.36 | S19: =R19-Q19 -> -862.64
A20: 45910 | B20: Soirée créa | C20: créa | D20: 145.41 | F20: Josephine Peronne | G20: oui
A21: 45911 | B21: Cyrano | C21: théâtre | D21: 180 | G21: oui
A22: 45911 | B22: Entretien | C22: salle ins | D22: 76.6 | F22: Alexis Derail | G22: oui
A23: 45912 | B23: Machine de Turing | C23: théâtre | D23: 270 | F23: Lucas Duhautois | G23: oui
A24: 45916 | B24: Tabliers | C24: gastro | D24: 49.82 | F24: Solène Losantos | G24: oui
A25: 45917 | B25: Radio France | C25: Classique | E25: 32 | G25: oui
A26: 45922 | B26: Entretien | C26: salle ins | D26: 26.05 | F26: Alexis Derail | G26: oui
A27: 45922 | B27: Vente matos | C27: salle ins | E27: 60 | F27: Alexis Derail | G27: oui
A28: 45930 | B28: créa Parrainage | C28: créa | D28: 78.41 | F28: Joséphinne Peronne | G28: oui
A29: 45934 | B29: Radio France 2 | C29: classique | E29: 40 | G29: oui
A30: 45934 | B30: th parrainage | C30: théâtre
A31: 45937 | B31: ampli | C31: salle ins | D31: 200 | F31: Alexis Derail | G31: oui
A32: 45937 | B32: frais dossier passace | C32: banque | D32: 50 | G32: oui
A33: 45940 | B33: radio france | C33: classique | D33: 60 | F33: Adam Bidi | G33: oui
A34: 45955 | B34: Machine de Turing | C34: théâtre | D34: 460 | F34: Lucas Duhautois | G34: oui
A35: 45955 | B35: remboursement | C35: Général | D35: 15 | F35: Alexandre | G35: oui
A36: 45957 | B36: matos gastro | C36: gastro | D36: 79.95 | F36: Alexandre | G36: oui
A37: 45958 | B37: créa octobre | C37: créa | D37: 52.38 | F37: Joséphine Peronne | G37: oui
A38: 45958 | B38: recettes parrainage | C38: Général | E38: 270
A39: 45958 | B39: recettes champs | C39: classique | E39: 30
A40: 45958 | B40: recettes Cyrano | C40: théâtre | E40: 152
...

Sheet Tableau croisé dynamique 4
M1: Dépenses | N1: Recettes | O1: Total net
L2: Total général | M2: =B14 -> 1540 | N2: =C14 -> 1002 | O2: =D14 -> -538
N6: Dépenses | O6: Recettes | P6: Total net
M7: Poles | N7: =SUM(B5:B8)+B14 -> 3518.43 | O7: =SUM(C5:C8)+C14 -> 1757 | P7: =-N7+O7 -> -1761.43
M8: Clubs | N8: =B4+B9+B12 -> 1190.74 | O8: =C4+C9+C12 -> 1128.35 | P8: =-N8+O8 -> -62.39
M9: Salle ins | N9: =B13 -> 1169.55 | O9: =C13 -> 650 | P9: =-N9+O9 -> -519.55
M10: Général | N10: =B3+B10 -> 3583.93 | O10: =C3+C10+C11 -> 6220 | P10: =-N10+O10 -> 2636.07
M11: Total | N11: =SUM(N7:N10) -> 9462.65 | O11: =SUM(O7:O10) -> 9755.35 | P11: =-N11+O11 -> 292.7

Sheet Général
A1: Date | B1: Motif | C1: Catégorie | D1: Dépense | E1: Recette | F1: Payeur | G1: Remboursé | H1: Facture
A2: 45833 | B2: Cotisation salle ins' | C2: Général | E2: 5 | F2: Killian Bujon
A3: 45839 | B3: parrainage | C3: Général | D3: 600 | H3: Th. Renaissance
A4: 45840 | B4: Constellation | C4: Général | E4: 500 | F4: PCV | H4: PCV
A5: 45900 | B5: BALM | C5: Général | D5: 369 | F5: Tom Back | G5: oui | J5: Total dépenses | K5: =SUM(D2:D200) -> 2237.72
A6: 45902 | B6: BALM | C6: Général | D6: 83.69 | F6: Alexandre Viot | G6: oui | J6: Total recettes | K6: =SUM(E2:E200) -> 5320
A7: 45902 | B7: BALM | C7: Général | D7: 41.34 | F7: Romain Lelaidier | G7: oui | J7: Total net | K7: =K6-K5 -> 3082.28
A8: 45906 | B8: Journée BDA | C8: Général | D8: 40 | F8: Romain Lelaidier | G8: oui
A9: 45955 | B9: remboursement | C9: Général | D9: 15 | F9: Alexandre | G9: oui
A10: 45958 | B10: recettes parrainage | C10: Général | E10: 270
A11: 45967 | B11: matos masterclass | C11: Général | D11: 90.25 | F11: Tom Back | G11: oui
A12: 46011 | B12: recettes Masterclass | C12: Général | E12: 770
A13: 46028 | B13: Cotiz | C13: Général | E13: 3775
A14: 46028 | B14: buffet concert BDA | C14: Général | D14: 201.87 | F14: Solène Losantos | G14: oui
A15: 46029 | B15: assurance | C15: Général | D15: 194.07
A16: 46038 | B16: concert Joly Rockets | C16: Général | D16: 102.5 | F16: Tom Back | G16: oui
A17: 46049 | B17: Concert couz | C17: Général | D17: 500

Sheet théâtre
A1: Date | B1: Motif | C1: Catégorie | D1: Dépense | E1: Recette | F1: Payeur | G1: Remboursé | H1: Facture
A2: 45829 | B2: Misanthrope + Scapin | C2: théâtre | D2: 450 | H2: Comédie Française
A3: 45912 | B3: Machine de Turing | C3: théâtre | D3: 270 | F3: Lucas Duhautois | G3: oui
A4: 45911 | B4: Cyrano | C4: théâtre | D4: 180
A5: 45955 | B5: Machine de Turing | C5: théâtre | D5: 460 | F5: Lucas Duhautois | G5: oui | K5: Total dépenses | L5: =SUM(D2:D200) -> 1540
A6: 45958 | B6: recettes Cyrano | C6: théâtre | E6: 152 | K6: Total recettes | L6: =SUM(E2:E200) -> 1002
A7: 45958 | B7: recettes Scapin | C7: théâtre | E7: 160 | K7: Total net | L7: =L6-L5 -> -538
A8: 45958 | B8: recettes Misanthrope | C8: théâtre | E8: 160
A9: 45958 | B9: recettes Turing | C9: théâtre | E9: 178
A10: 45995 | B10: Comédie Française | C10: théâtre | D10: 180
A11: 46011 | B11: recettes Edmond | C11: théâtre | E11: 258
A12: 46082 | B12: recettes Hamlet | C12: théâtre | E12: 94

Sheet banque
A1: Date | B1: Motif | C1: Catégorie | D1: Dépense | E1: Recette | F1: Payeur | G1: Remboursé | H1: Facture
A2: 45826 | B2: Frais dossier | C2: banque | D2: 50
A3: 45937 | B3: frais dossier passace | C3: banque | D3: 50 | G3: oui
K5: Total dépenses | L5: =SUM(D2:D200) -> 100
K6: Total recettes | L6: =SUM(E2:E200) -> 0
K7: Total net | L7: =L6-L5 -> -100

Sheet créa
A1: Date | B1: Motif | C1: Catégorie | D1: Dépense | E1: Recette | F1: Payeur | G1: Remboursé | H1: Facture
A2: 45829 | B2: soirée 1 | C2: créa | D2: 56.11 | F2: Josephine Peronne | G2: oui | H2: oui
A3: 45832 | B3: soirée 26/06 | C3: créa | D3: 50.28 | F3: Joséphine Peronne | G3: oui | H3: oui
A4: 45905 | B4: Soirée créa | C4: Créa | D4: 6.98 | F4: Romain Lelaidier | G4: oui | H4: oui
A5: 45910 | B5: Soirée créa | C5: créa | D5: 145.41 | F5: Josephine Peronne | G5: oui | H5: oui | K5: Total dépenses | L5: =SUM(D2:D200) -> 528.43
A6: 45930 | B6: créa Parrainage | C6: créa | D6: 78.41 | F6: Joséphinne Peronne | G6: oui | H6: oui | K6: Total recettes | L6: =SUM(E2:E200) -> 0
A7: 45958 | B7: créa octobre | C7: créa | D7: 52.38 | F7: Joséphine Peronne | G7: oui | H7: oui | K7: Total net | L7: =L6-L5 -> -528.43
A8: 46091 | B8: soirée créa | C8: créa | D8: 138.86 | F8: Luigi Romain | G8: oui

Sheet CCMP
A1: Date | B1: Motif | C1: Catégorie | D1: Dépense | E1: Recette | F1: Payeur | G1: Remboursé | H1: Facture
A2: 45746 | B2: Film | C2: CCMP | D2: 3.99 | F2: Mikhail | G2: oui
K5: Total dépenses | L5: =SUM(D2:D200) -> 3.99
K6: Total recettes | L6: =SUM(E2:E200) -> 0
K7: Total net | L7: =L6-L5 -> -3.99

Sheet gastro
A1: Date | B1: Motif | C1: Catégorie | D1: Dépense | E1: Recette | F1: Payeur | G1: Remboursé | H1: Facture
A2: 45817 | B2: dettes | C2: Gastro | D2: 13.34 | F2: Solène Losantos | G2: oui
A3: 45824 | B3: buffet concert BDA | C3: Gastro | D3: 246.79 | F3: Solène Losantos | G3: oui
A4: 45916 | B4: Tabliers | C4: gastro | D4: 49.82 | F4: Solène Losantos | G4: oui
A5: 45957 | B5: matos gastro | C5: gastro | D5: 79.95 | F5: Alexandre | G5: oui | K5: Total dépenses | L5: =SUM(D2:D200) -> 984.58
A6: 45963 | B6: atelier | C6: gastro | D6: 125.21 | F6: Alexandre | G6: oui | K6: Total recettes | L6: =SUM(E2:E200) -> 798.35
A7: 46005 | B7: erasmus days | C7: gastro | D7: 214.82 | F7: Solène Losantos | G7: oui | K7: Total net | L7: =L6-L5 -> -186.23
A8: 46028 | B8: Meuhsterchef | C8: gastro | D8: 83.61 | F8: Solène Losantos | G8: oui
A9: 46038 | B9: Subventions PSLweek | C9: gastro | E9: 200
A10: 46063 | B10: buffet concert BDA | C10: Gastro | D10: 145.39 | F10: Remy Level | G10: oui
A11: 46072 | B11: buffet concert noel | C11: Gastro | D11: 25.65 | F11: Gabriel Vds | G11: oui
A12: 46120 | B12: Buffet 3A | C12: Gastro | E12: 598.35

Sheet classique
A1: Date | B1: Motif | C1: Catégorie | D1: Dépense | E1: Recette | F1: Payeur | G1: Remboursé | H1: Facture
A2: 45818 | B2: concerts | C2: classique | D2: 502 | F2: Adam Bidi | G2: oui
A3: 45917 | B3: Radio France | C3: classique | E3: 32 | G3: oui
A4: 45934 | B4: Radio France 2 | C4: classique | E4: 40 | G4: oui
A5: 45940 | B5: radio france | C5: classique | D5: 60 | F5: Adam Bidi | G5: oui | K5: Total dépenses | L5: =SUM(D2:D200) -> 724
A6: 45958 | B6: recettes champs | C6: classique | E6: 30 | G6: oui | K6: Total recettes | L6: =SUM(E2:E200) -> 352
A7: 45980 | B7: places | C7: classique | D7: 162 | F7: Bidi | G7: oui | K7: Total net | L7: =L6-L5 -> -372
A8: 45994 | B8: recettes philharmonie | C8: classique | E8: 29 | G8: oui
A9: 45995 | B9: recettes M radio | C9: classique | E9: 39 | G9: oui
A10: 46011 | B10: recettes Kissin | C10: classique | E10: 30
A11: 46011 | B11: recettes Chopin | C11: classique | E11: 33
A12: 46038 | B12: recettes philharmonie | C12: classique | E12: 31
A13: 46055 | B13: recettes champs | C13: classique | E13: 34
A14: 46082 | B14: recettes M radio | C14: classique | E14: 54

Sheet Salle ins
A1: Date | B1: Motif | C1: Catégorie | D1: Dépense | E1: Recette | F1: Payeur | G1: Remboursé | H1: Facture
A2: 45760 | B2: Piles | C2: salle ins | D2: 7.1 | F2: Alexis Derail | G2: oui
A3: 45895 | B3: Vente matos | C3: salle ins | E3: 70 | F3: Alexis Derail | G3: oui
A4: 45911 | B4: Entretien | C4: salle ins | D4: 76.6 | F4: Alexis Derail | G4: oui
A5: 45922 | B5: Entretien | C5: salle ins | D5: 26.05 | F5: Alexis Derail | G5: oui | K5: Total dépenses | L5: =SUM(D2:D200) -> 1169.55
A6: 45922 | B6: Vente matos | C6: salle ins | E6: 60 | F6: Alexis Derail | G6: oui | K6: Total recettes | L6: =SUM(E2:E200) -> 900
A7: 45937 | B7: ampli | C7: salle ins | D7: 200 | F7: Alexis Derail | G7: oui | K7: Total net | L7: =L6-L5 -> -269.55
A8: 45966 | B8: matos | C8: salle ins | D8: 204.8 | F8: Derail | G8: oui
A9: 45980 | B9: matos | C9: salle ins | D9: 400 | F9: Alexis Derail | G9: oui
A10: 45996 | B10: matos | C10: salle ins | D10: 10 | F10: Alexis Derail | G10: oui
A11: 46037 | B11: matos | C11: salle ins | D11: 197 | F11: Alexis Derail | G11: oui
A12: 46039 | B12: matos | C12: salle ins | D12: 33 | F12: Alexis Derail | G12: oui
A13: 46053 | B13: Vente matos | C13: salle ins | E13: 390
A14: 46081 | B14: Vente matos | C14: Salle ins | E14: 100
A15: 46092 | B15: matos | C15: salle ins | D15: 15 | F15: Gabin Sagot | G15: oui
A16: 46093 | B16: vente matos | C16: salle ins | E16: 30
A17: 46120 | B17: Junior ENS Saclay | C17: Général | E17: 250

Sheet Comédie
A1: Date | B1: Motif | C1: Catégorie | D1: Dépense | E1: Recette | F1: Payeur | G1: Remboursé | H1: Facture
A2: 45976 | B2: places | C2: Comédie | D2: 625
A3: 46011 | B3: recettes J.Baker | C3: Comédie | E3: 403
K5: Total dépenses | L5: =SUM(D2:D200) -> 625
K6: Total recettes | L6: =SUM(E2:E200) -> 403
K7: Total net | L7: =L6-L5 -> -222

Sheet PapiMaMine
A1: Date | B1: Motif | C1: Catégorie | D1: Dépense | E1: Recette | F1: Payeur | G1: Remboursé | H1: Facture
A2: 45997 | B2: matos | C2: PapiMaMine | D2: 166.84 | F2: Elena Drematcheff | G2: oui
A3: 46028 | B3: PCV | C3: PapiMaMine | E3: 330
A4: 46063 | B4: fil | C4: PapiMaMine | D4: 9.4 | F4: Elena Drematcheff | G4: oui
K5: Total dépenses | L5: =SUM(D2:D200) -> 176.24
K6: Total recettes | L6: =SUM(E2:E200) -> 330
K7: Total net | L7: =L6-L5 -> 153.76

Sheet ciné
A1: Date | B1: Motif | C1: Catégorie | D1: Dépense | E1: Recette | F1: Payeur | G1: Remboursé | H1: Facture
A2: 46004 | B2: ciné | C2: ciné | D2: 56 | F2: Romaric Ligeret | G2: oui
A3: 46045 | B3: places | C3: ciné | D3: 45 | F3: Romaric Ligeret | G3: oui
A4: 46053 | B4: proj | C4: CCMP | D4: 25.93 | F4: Mikhail Kataevskii | G4: oui
K5: Total dépenses | L5: =SUM(D2:D200) -> 126.93
K6: Total recettes | L6: =SUM(E2:E200) -> 0
K7: Total net | L7: =L6-L5 -> -126.93
